Workbook

Sheet AFIRMACIONES
A1: ENEAGRAMA: Mapa de autoidentificación personal. | HO1: =(+C3-C5)/365.25 -> 0
A2: POR FAVOR COMPLETA LOS SIGUIENTES DATOS PERSONALES
A3: Fecha: | F3: Por favor poner en números: día (dos cifras) / mes (dos cifras) / año (cuatro cifras)
A4: Nombre:
A5: Fecha de Nacimiento: | F5: Por favor poner en números: día (dos cifras) / mes (dos cifras) / año (cuatro cifras)
A6: Edad: | D6: Años
A7: Sexo: | E7: Por favor escribir según corresponda: FEMENINO / MASCULINO
A8: Estado Civil: | E8: Por favor escribir según corresponda: SOLTERO / CASADO / EN PAREJA / DE NOVIO / VIUDO / DIVORCIADO
A9: Ocupación o Profesión:
A10: Signo del zodíaco | D10: Aries | E10: Si tu signo del zodíaco es ARIES (21/03 al 20/04) , coloca un 1 en el casillero blanco de la izquierda | N10: =+C10 -> 0 | O10: 1
D11: Leo | E11: Si tu signo del zodíaco es LEO (24/07 al 23/08), coloca un 1 en el casillero blanco de la izquierda | N11: =+C11 -> 0 | O11: 8
D12: Sagitario | E12: Si tu signo del zodíaco es SAGITARIO (23/11 al 21/12), coloca un 1 en el casillero blanco de la izquierda | N12: =+C12 -> 0 | O12: 7
D13: Tauro | E13: Si tu signo del zodíaco es TAURO (21/04 al 20/05), coloca un 1 en el casillero blanco de la izquierda | N13: =+C13 -> 0 | O13: 3
D14: Virgo | E14: Si tu signo del zodíaco es VIRGO (24/08 al 23/09), coloca un 1 en el casillero blanco de la izquierda | N14: =+C14 -> 0 | O14: 1
D15: Capricornio | E15: Si tu signo del zodíaco es CAPRICORNIO (22/12 al 20/01), coloca un 1 en el casillero blanco de la izquierda | N15: =+C15 -> 0 | O15: 6
D16: Géminis | E16: Si tu signo del zodíaco es GEMINIS (21/05 al 21/06), coloca un 1 en el casillero blanco de la izquierda | N16: =+C16 -> 0 | O16: 5
D17: Libra | E17: Si tu signo del zodíaco es LIBRA (24/09 al 22/10), coloca un 1 en el casillero blanco de la izquierda | N17: =+C17 -> 0 | O17: 4
D18: Acuario | E18: Si tu signo del zodíaco es ACUARIO (21/01 al 19/02), coloca un 1 en el casillero blanco de la izquierda | N18: =+C18 -> 0 | O18: 4
D19: Cáncer | E19: Si tu signo del zodíaco es CÁNCER (22/06 al 23/07), coloca un 1 en el casillero blanco de la izquierda | N19: =+C19 -> 0 | O19: 2
D20: Escorpio | E20: Si tu signo del zodíaco es ESCORPIO (23/10 al 22/11), coloca un 1 en el casillero blanco de la izquierda | N20: =+C20 -> 0 | O20: 8
D21: Piscis | E21: Si tu signo del zodíaco es PISCIS ( 20/02 al 20/03), coloca un 1 en el casillero blanco de la izquierda | N21: =+C21 -> 0 | O21: 9
A22: MUY IMPORTANTE: Leer bien las consignas ANTES DE INICIAR EL TRABAJO:
A23: CONSIGNA 1:
A24: A continuación encontrarás una serie de afirmaciones, si te identificas con la afirmación debes escribir el N° "1" en el recuadro en blanco a la
A25: izquierda de la misma; si no te identificas con la afirmación debes dejar el recuadro en blanco.
A26: Es muy importante que respondas este cuestionario pensando en cómo realmente eres o sientes, no cómo te gustaría sentir o ser.
A27: Debes completarlo de una sola vez, sin detenerte mucho en cada afirmación y sin revisar las respuestas, es decir, tratando de responder en
A28: forma espontánea. Si dudas, puedes responder en base a cómo hubieras respondido tiempo atrás, por ejemplo cuando eras adolescente;
A29: si continua la duda, déjalo en blanco.
A30: 1 | C30: Protejo a quienes se encuentran bajo mi autoridad. | N30: 8
A31: 2 | C31: Me cuesta convencerme de que aquello que compré fue una buena decisión. | N31: 6
A32: 3 | C32: No hay nada tan urgente que no pueda esperar hasta mañana. | N32: 9
A33: 4 | C33: Siento que soy una persona apreciada por los demás a través de mis logros. | N33: 3
A34: 5 | C34: Me duele mucho cuando mis amistades se reúnen y no me participan. | N34: 2
A35: 6 | C35: El dinero es secundario, sólo sirve para atender las necesidades. | N35: 5
A36: 7 | C36: Suelen acusarme de ser una persona indisciplinada, dispersa, inquieta, superficial. | N36: 7
A37: 8 | C37: Me considero una persona sensible, auténtica, especial y profunda. | N37: 4
A38: 9 | C38: A menudo un defecto final arruina el conjunto. | N38: 1
A39: 10 | C39: Puedo arbitrar desapasionadamente, porque para mí las dos partes son iguales. | N39: 9
A40: 11 | C40: Es frecuente que otras personas carezcan de capacidad para comprender mis sentimientos. | N40: 4
...

Sheet ENEAGRAMA
B1: Respuesta | C1: Tipología | D1: TIPOLOGIAS | M1: Respuesta | N1: Tipología | O1: TIPOLOGIAS | X1: Respuesta | Y1: Tipología | Z1: TIPOLOGIAS | AN1: CICLO | AO1: ETAPA | AP1: MIEDO | AR1: ACTITUD | AT1: ELEMENTO | AV1: NIVEL CONCIENTE | AX1: SENTIDO
D2: 1 | E2: 2 | F2: 3 | G2: 4 | H2: 5 | I2: 6 | J2: 7 | K2: 8 | L2: 9 | O2: 1 | P2: 2 | Q2: 3 | R2: 4 | S2: 5 | T2: 6 | U2: 7 | V2: 8 | W2: 9 | Z2: 1 | AA2: 2 | AB2: 3 | AC2: 4 | AD2: 5 | AE2: 6 | AF2: 7 | AG2: 8 | AH2: 9 | AJ2: =+IF(AND(AFIRMACIONES!$C$6>=AL2,AFIRMACIONES!$C$6<=AM2),1,0) -> 0 | AK2: 1 | AL2: 1 | AM2: 6 | AN2: Afirmación | AO2: De O a 7 Años | AP2: A la DISTANCIA, al abandono. Lo agrava la muerte de un ser querido o una mascota o la separación de los padres. | AR2: PRESENCIA, estar presente con el corazón. Presencia cualitativa y cuantitativa. Acompañarlo. Necesita la figura materna y paterna. | AT2: El AGUA, disuelve el miedo. Recuerda al líquido amniótico. Es sanante. | AV2: YO. Afianzar el yo personal. Poner límites claros y precisos sin mayores explicaciones. Sólo en esta etapa funciona el "premio - castigo". | AX2: GUSTO. Es importante variar su alimentación para que sepa que existe lo dulce, lo salado y lo amargo. Aprende que no todo lo que le gusta es nutritivo.
B3: 1 | C3: 8 | K3: =+AFIRMACIONES!B30 -> 0 | M3: 100 | N3: 5 | S3: =+AFIRMACIONES!B129 -> 0 | X3: 199 | Y3: 7 | AF3: =+AFIRMACIONES!B228 -> 0 | AJ3: =+IF(AND(AFIRMACIONES!$C$6>=AL3,AFIRMACIONES!$C$6<=AM3),1,0) -> 0 | AK3: 2 | AL3: 7 | AM3: 13 | AN3: Afirmación | AO3: De 7 a 14 Años | AP3: A la CERCANÍA, a LOS OTROS, a que nadie lo quiera, no agradarle al otro, al rechazo o a que le hagan mal. | AR3: AUTONOMÍA, ayudarlo a que enfrente las situaciones por sí mismo y decidan. Estar cerca y acompañarlo. Darle explicaciones. "La norma se apoya en un valor" | AT3: El FUEGO. Inconscientemente el jugar con fuego ayuda a disolver el miedo (campamentos fogones) | AV3: SOCIAL. Dignidad: Palabra sagrada. Evitar la burla. Nace la verdadera solidaridad que disuelve el miedo al otro. Enseñarle a valorarse y el valor del otro. | AX3: VISTA. Enseñar a ver más allá, a través de un microscopio, un telescopio o acostarse en el pasto y mirar el cielo. Ver juntos videos o películas y comentarlas.
B4: 2 | C4: 6 | I4: =+AFIRMACIONES!B31 -> 0 | M4: 101 | N4: 7 | U4: =+AFIRMACIONES!B130 -> 0 | X4: 200 | Y4: 3 | AB4: =+AFIRMACIONES!B229 -> 0 | AJ4: =+IF(AND(AFIRMACIONES!$C$6>=AL4,AFIRMACIONES!$C$6<=AM4),1,0) -> 0 | AK4: 3 | AL4: 14 | AM4: 20 | AN4: Afirmación | AO4: De 14 a 21 Años | AP4: Al CAMBIO. Todo cambia en la vida. Se constituye como persona. Necesita tomar distancia. Se produce el proceso hormonal de la adolescencia. | AR4: SEGURIDAD. Dejarlo actuar, pero estar cuando lo necesite. Ser un referente o "faro". Que sepa que "puede contar con uno". Mostrarle coherencia y consistencia. | AT4: El AIRE. Incentivar la vida al aire libre. Trabajar la respiración. Ir de campamento, correr, andar en bicicleta. | AV4: EXISTENCIAL. Etapa de preguntas sobre la vida y la muerte, aprender a ser crítico, a cuestionarse. Flexibilizar las normas y mantener firmes los valores. | AX4: TACTO. La música y el arte lo preparan para el amor. Hacer trabajos manuales, artesanías, sentir las cosas para lograr sensibilidad. Tocar un instrumento
B5: 3 | C5: 9 | L5: =+AFIRMACIONES!B32 -> 0 | M5: 102 | N5: 6 | T5: =+AFIRMACIONES!B131 -> 0 | X5: 201 | Y5: 4 | AC5: =+AFIRMACIONES!B230 -> 0 | AJ5: =+IF(AND(AFIRMACIONES!$C$6>=AL5,AFIRMACIONES!$C$6<=AM5),1,0) -> 0 | AK5: 4 | AL5: 21 | AM5: 27 | AN5: Afirmación | AO5: De 21 a 28 Años | AP5: A la CONTINUIDAD, a perder la libertad, a la rutina. Le cuesta asumir compromisos. La rutina está dentro de cada uno. | AR5: CREATIVIDAD. Lograr una actitud distinta hacia lo cotidiano, que sea placentero. Hacer extraordinario lo ordinario de cada día | AT5: La TIERRA enseña que no todo en la vida es invierno o verano, también existe la primavera y el otoño, la rutina no existe, son ciclos naturales. | AV5: TRANSPERSONAL. Etapa de los ¿para qué?. Encontrar el verdadero sentido de la vida. Buscar la misión de vida. ¿Para qué estoy? ¿A dónde voy? | AX5: OLFATO. Relacionado con la glándula pineal. Tiene que ver con el sentido común. Actualmente es el sentido menos desarrollado.
B6: 4 | C6: 3 | F6: =+AFIRMACIONES!B33 -> 0 | M6: 103 | N6: 3 | Q6: =+AFIRMACIONES!B132 -> 0 | X6: 202 | Y6: 9 | AH6: =+AFIRMACIONES!B231 -> 0 | AJ6: =+IF(AND(AFIRMACIONES!$C$6>=AL6,AFIRMACIONES!$C$6<=AM6),1,0) -> 0 | AK6: 5 | AL6: 28 | AM6: 41 | AN6: Afirmación | AO6: De 28 a 35 y de 35 a 42 Años | AP6: A PERDER la figura, la pareja, la virilidad, el dinero, la vida, lo que me gusta hacer. Miedo a perder el tiempo y la juventud. | AR6: SER. El tener compulsivamente disminuye solo momentáneamente el miedo a perder. Poner tiempo y energía para el ser, crecimiento interior. | AT6: La LUZ. Contacto con el sol para aprender a sentir la luz. Tiempo para tener claridad, para la soledad, no aislamiento, sino encontrarse con sí mismo. | AV6: UNIDAD. Conciencia comunitaria. Pensar en plural: "no soy, somos", "no es mío, es nuestro". Estar en armonía y agradecer y sonreír a la vida. | AX6: OÍDO. Escuchar el doble de lo que se habla. Aprender a escuchar y a escucharse. Prestar atención a lo sagrado en uno. Estar a la escucha.
B7: 5 | C7: 2 | E7: =+AFIRMACIONES!B34 -> 0 | M7: 104 | N7: 4 | R7: =+AFIRMACIONES!B133 -> 0 | X7: 203 | Y7: 2 | AA7: =+AFIRMACIONES!B232 -> 0 | AJ7: =+IF(AND(AFIRMACIONES!$C$6>=AL7,AFIRMACIONES!$C$6<=AM7),1,0) -> 0 | AK7: 6 | AL7: 42 | AM7: 48 | AN7: Transformación | AO7: De 42 a 49 Años | AP7: A la CONTINUIDAD, a la rutina. TENER: Aferrarse a los bienes y sólo tomarse recreos placenteros. Es necesario consolidar el SER. | AR7: CREATIVIDAD. Lograr una actitud distinta hacia lo cotidiano, hacer extraordinario lo ordinario. SER: Expansión de la persona | AT7: La TIERRA: energía de vida y de creación. Tomar contacto con la tierra, caminar, atender el jardín, regar. | AV7: TRANSPERSONAL. No encerrarse en la preocupaciones inmediatas. Focalizarse en el Ideal de Vida | AX7: OLFATO. Actuar con sentido común. Desarrolla el hemisferio derecho del cerebro. Disfrutar las esencias y sabiduría oculta en los aromas.
B8: 6 | C8: 5 | H8: =+AFIRMACIONES!B35 -> 0 | M8: 105 | N8: 2 | P8: =+AFIRMACIONES!B134 -> 0 | X8: 204 | Y8: 1 | Z8: =+AFIRMACIONES!B233 -> 0 | AJ8: =+IF(AND(AFIRMACIONES!$C$6>=AL8,AFIRMACIONES!$C$6<=AM8),1,0) -> 0 | AK8: 7 | AL8: 49 | AM8: 55 | AN8: Transformación | AO8: De 49 a 56 Años | AP8: Al CAMBIO, temor por los cambios físicos que comienzan: andropausia, menopausia. Nido vacío lleva al reencuentro de la pareja. La experiencia ayuda a ser guías. | AR8: SEGURIDAD, el tener da seguridad afuera: en lo material, el éxito; acción dirigida al trabajo para llenar vacíos. Pero el SER da seguridad en la plenitud personal. Amistad. | AT8: El AIRE, incentivar la vida al aire libre. Vivir sin fronteras, liberarse de las emociones. | AV8: EXISTENCIAL. El tener lleva a caer en la crítica, el pesimismo. El SER implica momento de cambios auténticos. Persona positiva que colabora y participa por el bien. | AX8: TACTO. Momento de sacar a la luz hobbies latentes. Masajes. Abrazos. Redescubrir el amor en la pareja.
B9: 7 | C9: 7 | J9: =+AFIRMACIONES!B36 -> 0 | M9: 106 | N9: 1 | O9: =+AFIRMACIONES!B135 -> 0 | X9: 205 | Y9: 8 | AG9: =+AFIRMACIONES!B234 -> 0 | AJ9: =+IF(AND(AFIRMACIONES!$C$6>=AL9,AFIRMACIONES!$C$6<=AM9),1,0) -> 0 | AK9: 8 | AL9: 56 | AM9: 62 | AN9: Transformación | AO9: De 56 a 63 Años | AP9: A la CERCANÍA A LOS OTROS, a robos, a sufrir violencia. Lleva a la persona a encerrase, no salir. Miedo a lo que puede pasar a los hijos y nietos. | AR9: AUTONOMÍA. No dejar de tomar recaudos, pero abrirse a la vida. Participar del "bien común" | AT9: El FUEGO le aporta vitalidad renovadora. El asado, lo culinario, cocinar para los demás con amor. | AV9: SOCIAL. Servicio social a través de lo experimentado. Solidaridad y participación. No caer en la amargura y la desesperanza | AX9: VISTA. Ejercitar la capacidad de asombro. Aprender cosas nuevas. Ser visionarios.
B10: 8 | C10: 4 | G10: =+AFIRMACIONES!B37 -> 0 | M10: 107 | N10: 8 | V10: =+AFIRMACIONES!B136 -> 0 | X10: 206 | Y10: 6 | AE10: =+AFIRMACIONES!B235 -> 0 | AJ10: =+IF(AND(AFIRMACIONES!$C$6>=AL10,AFIRMACIONES!$C$6<=AM10),1,0) -> 0 | AK10: 9 | AL10: 63 | AM10: 69 | AN10: Transformación | AO10: De 63 a 70 Años | AP10: A la DISTANCIA, a sentirse inútil, sensación de abandono. Reclama presencia, tiempo y energía. | AR10: PRESENCIA. Acompañamiento, presencia y servicio no invasivos, no tóxicos. Sabiduría en límites sanos. | AT10: El AGUA disuelve el miedo. Es sanante. Alarma de problemas psicológicos si hay rechazo a la higiene. | AV10: YO. Si se afirma el ego = Tóxico, si se afirma la conciencia = Sabio. Autoestima sana. | AX10: GUSTO. Saborear = sabiduría. Cuidarse y comer bien. En sombra hipocondríacos.
B11: 9 | C11: 1 | D11: =+AFIRMACIONES!B38 -> 0 | M11: 108 | N11: 9 | W11: =+AFIRMACIONES!B137 -> 0 | X11: 207 | Y11: 5 | AD11: =+AFIRMACIONES!B236 -> 0 | AJ11: =+IF(AND(AFIRMACIONES!$C$6>=AL11,AFIRMACIONES!$C$6<=AM11),1,0) -> 0 | AK11: 10 | AL11: 70 | AM11: 90 | AN11: Transformación | AO11: De 70 en adelante | AP11: A PERDER, a la muerte. La muerte como final o como paso a la trascendencia. | AR11: SER. Momento de confirmar las decisiones fundamentales de la vida. Durar o madurar. Servir. | AT11: La LUZ, tomar contacto con el sol. Los ojos son las ventanas del alma. Ser faros que iluminan. (una cosa es querer brillar y otra ser luz). | AV11: UNIDAD. La casa de los abuelos es el corazón de la familia. Tener gratitud y alegría. | AX11: OÍDO. Ser expertos en el arte de escuchar. En la sombra hablar de sí, criticar y dar consejos que no le piden.
B12: 10 | C12: 9 | L12: =+AFIRMACIONES!B39 -> 0 | M12: 109 | N12: 2 | P12: =+AFIRMACIONES!B138 -> 0 | X12: 208 | Y12: 5 | AD12: =+AFIRMACIONES!B237 -> 0
B13: 11 | C13: 4 | G13: =+AFIRMACIONES!B40 -> 0 | M13: 110 | N13: 7 | U13: =+AFIRMACIONES!B139 -> 0 | X13: 209 | Y13: 2 | AA13: =+AFIRMACIONES!B238 -> 0
B14: 12 | C14: 7 | J14: =+AFIRMACIONES!B41 -> 0 | M14: 111 | N14: 8 | V14: =+AFIRMACIONES!B140 -> 0 | X14: 210 | Y14: 3 | AB14: =+AFIRMACIONES!B239 -> 0
B15: 13 | C15: 8 | K15: =+AFIRMACIONES!B42 -> 0 | M15: 112 | N15: 5 | S15: =+AFIRMACIONES!B141 -> 0 | X15: 211 | Y15: 1 | Z15: =+AFIRMACIONES!B240 -> 0
B16: 14 | C16: 3 | F16: =+AFIRMACIONES!B43 -> 0 | M16: 113 | N16: 3 | Q16: =+AFIRMACIONES!B142 -> 0 | X16: 212 | Y16: 6 | AE16: =+AFIRMACIONES!B241 -> 0
B17: 15 | C17: 1 | D17: =+AFIRMACIONES!B44 -> 0 | M17: 114 | N17: 4 | R17: =+AFIRMACIONES!B143 -> 0 | X17: 213 | Y17: 9 | AH17: =+AFIRMACIONES!B242 -> 0
B18: 16 | C18: 6 | I18: =+AFIRMACIONES!B45 -> 0 | M18: 115 | N18: 6 | T18: =+AFIRMACIONES!B144 -> 0 | X18: 214 | Y18: 4 | AC18: =+AFIRMACIONES!B243 -> 0
B19: 17 | C19: 2 | E19: =+AFIRMACIONES!B46 -> 0 | M19: 116 | N19: 1 | O19: =+AFIRMACIONES!B145 -> 0 | X19: 215 | Y19: 8 | AG19: =+AFIRMACIONES!B244 -> 0
B20: 18 | C20: 5 | H20: =+AFIRMACIONES!B47 -> 0 | M20: 117 | N20: 9 | W20: =+AFIRMACIONES!B146 -> 0 | X20: 216 | Y20: 7 | AF20: =+AFIRMACIONES!B245 -> 0
B21: 19 | C21: 8 | K21: =+AFIRMACIONES!B48 -> 0 | M21: 118 | N21: 3 | Q21: =+AFIRMACIONES!B147 -> 0 | X21: 217 | Y21: 3 | AB21: =+AFIRMACIONES!B246 -> 0
B22: 20 | C22: 5 | H22: =+AFIRMACIONES!B49 -> 0 | M22: 119 | N22: 7 | U22: =+AFIRMACIONES!B148 -> 0 | X22: 218 | Y22: 4 | AC22: =+AFIRMACIONES!B247 -> 0
B23: 21 | C23: 2 | E23: =+AFIRMACIONES!B50 -> 0 | M23: 120 | N23: 1 | O23: =+AFIRMACIONES!B149 -> 0 | X23: 219 | Y23: 7 | AF23: =+AFIRMACIONES!B248 -> 0
B24: 22 | C24: 4 | G24: =+AFIRMACIONES!B51 -> 0 | M24: 121 | N24: 5 | S24: =+AFIRMACIONES!B150 -> 0 | X24: 220 | Y24: 9 | AH24: =+AFIRMACIONES!B249 -> 0
B25: 23 | C25: 7 | J25: =+AFIRMACIONES!B52 -> 0 | M25: 122 | N25: 2 | P25: =+AFIRMACIONES!B151 -> 0 | X25: 221 | Y25: 8 | AG25: =+AFIRMACIONES!B250 -> 0
B26: 24 | C26: 1 | D26: =+AFIRMACIONES!B53 -> 0 | M26: 123 | N26: 4 | R26: =+AFIRMACIONES!B152 -> 0 | X26: 222 | Y26: 5 | AD26: =+AFIRMACIONES!B251 -> 0
B27: 25 | C27: 9 | L27: =+AFIRMACIONES!B54 -> 0 | M27: 124 | N27: 8 | V27: =+AFIRMACIONES!B153 -> 0 | X27: 223 | Y27: 1 | Z27: =+AFIRMACIONES!B252 -> 0
B28: 26 | C28: 3 | F28: =+AFIRMACIONES!B55 -> 0 | M28: 125 | N28: 9 | W28: =+AFIRMACIONES!B154 -> 0 | X28: 224 | Y28: 2 | AA28: =+AFIRMACIONES!B253 -> 0
B29: 27 | C29: 6 | I29: =+AFIRMACIONES!B56 -> 0 | M29: 126 | N29: 6 | T29: =+AFIRMACIONES!B155 -> 0 | X29: 225 | Y29: 6 | AE29: =+AFIRMACIONES!B254 -> 0
B30: 28 | C30: 2 | E30: =+AFIRMACIONES!B57 -> 0 | M30: 127 | N30: 6 | T30: =+AFIRMACIONES!B156 -> 0 | X30: 226 | Y30: 1 | Z30: =+AFIRMACIONES!B255 -> 0
B31: 29 | C31: 3 | F31: =+AFIRMACIONES!B58 -> 0 | M31: 128 | N31: 1 | O31: =+AFIRMACIONES!B157 -> 0 | X31: 227 | Y31: 2 | AA31: =+AFIRMACIONES!B256 -> 0
B32: 30 | C32: 8 | K32: =+AFIRMACIONES!B59 -> 0 | M32: 129 | N32: 2 | P32: =+AFIRMACIONES!B158 -> 0 | X32: 228 | Y32: 5 | AD32: =+AFIRMACIONES!B257 -> 0
B33: 31 | C33: 5 | H33: =+AFIRMACIONES!B60 -> 0 | M33: 130 | N33: 8 | V33: =+AFIRMACIONES!B159 -> 0 | X33: 229 | Y33: 6 | AE33: =+AFIRMACIONES!B258 -> 0
B34: 32 | C34: 1 | D34: =+AFIRMACIONES!B61 -> 0 | M34: 131 | N34: 3 | Q34: =+AFIRMACIONES!B160 -> 0 | X34: 230 | Y34: 8 | AG34: =+AFIRMACIONES!B259 -> 0
B35: 33 | C35: 6 | I35: =+AFIRMACIONES!B62 -> 0 | M35: 132 | N35: 7 | U35: =+AFIRMACIONES!B161 -> 0 | X35: 231 | Y35: 9 | AH35: =+AFIRMACIONES!B260 -> 0
B36: 34 | C36: 9 | L36: =+AFIRMACIONES!B63 -> 0 | M36: 133 | N36: 5 | S36: =+AFIRMACIONES!B162 -> 0 | X36: 232 | Y36: 4 | AC36: =+AFIRMACIONES!B261 -> 0
B37: 35 | C37: 4 | G37: =+AFIRMACIONES!B64 -> 0 | M37: 134 | N37: 4 | R37: =+AFIRMACIONES!B163 -> 0 | X37: 233 | Y37: 7 | AF37: =+AFIRMACIONES!B262 -> 0
B38: 36 | C38: 7 | J38: =+AFIRMACIONES!B65 -> 0 | M38: 135 | N38: 9 | W38: =+AFIRMACIONES!B164 -> 0 | X38: 234 | Y38: 3 | AB38: =+AFIRMACIONES!B263 -> 0
B39: 37 | C39: 4 | G39: =+AFIRMACIONES!B66 -> 0 | M39: 136 | N39: 9 | W39: =+AFIRMACIONES!B165 -> 0 | X39: 235 | Y39: 8 | AG39: =+AFIRMACIONES!B264 -> 0
B40: 38 | C40: 5 | H40: =+AFIRMACIONES!B67 -> 0 | M40: 137 | N40: 6 | T40: =+AFIRMACIONES!B166 -> 0 | X40: 236 | Y40: 9 | AH40: =+AFIRMACIONES!B265 -> 0
...

Sheet PLANILLA PARA EL FORMADOR
B1: Respuesta | C1: Tipología | D1: TIPOLOGIAS | M1: Respuesta | N1: Tipología | O1: TIPOLOGIAS | X1: Respuesta | Y1: Tipología | Z1: TIPOLOGIAS | AN1: CICLO | AO1: ETAPA | AP1: MIEDO | AR1: ACTITUD | AT1: ELEMENTO | AV1: NIVEL CONCIENTE | AX1: SENTIDO
D2: 1 | E2: 2 | F2: 3 | G2: 4 | H2: 5 | I2: 6 | J2: 7 | K2: 8 | L2: 9 | O2: 1 | P2: 2 | Q2: 3 | R2: 4 | S2: 5 | T2: 6 | U2: 7 | V2: 8 | W2: 9 | Z2: 1 | AA2: 2 | AB2: 3 | AC2: 4 | AD2: 5 | AE2: 6 | AF2: 7 | AG2: 8 | AH2: 9 | AJ2: =+IF(AND(AFIRMACIONES!$C$6>=AL2,AFIRMACIONES!$C$6<=AM2),1,0) -> 0 | AK2: 1 | AL2: 1 | AM2: 6 | AN2: Afirmación | AO2: De O a 7 Años | AP2: A la DISTANCIA, al abandono. Lo agrava la muerte de un ser querido o una mascota o la separación de los padres. | AR2: PRESENCIA, estar presente con el corazón. Presencia cualitativa y cuantitativa. Acompañarlo. Necesita la figura materna y paterna. | AT2: El AGUA, disuelve el miedo. Recuerda al líquido amniótico. Es sanante. | AV2: YO. Afianzar el yo personal. Poner límites claros y precisos sin mayores explicaciones. Sólo en esta etapa funciona el "premio - castigo". | AX2: GUSTO. Es importante variar su alimentación para que sepa que existe lo dulce, lo salado y lo amargo. Aprende que no todo lo que le gusta es nutritivo.
B3: 1 | C3: 8 | K3: =+AFIRMACIONES!B30 -> 0 | M3: 100 | N3: 5 | S3: =+AFIRMACIONES!B129 -> 0 | X3: 199 | Y3: 7 | AF3: =+AFIRMACIONES!B228 -> 0 | AJ3: =+IF(AND(AFIRMACIONES!$C$6>=AL3,AFIRMACIONES!$C$6<=AM3),1,0) -> 0 | AK3: 2 | AL3: 7 | AM3: 13 | AN3: Afirmación | AO3: De 7 a 14 Años | AP3: A la CERCANÍA, a LOS OTROS, a que nadie lo quiera, no agradarle al otro, al rechazo o a que le hagan mal. | AR3: AUTONOMÍA, ayudarlo a que enfrente las situaciones por sí mismo y decidan. Estar cerca y acompañarlo. Darle explicaciones. "La norma se apoya en un valor" | AT3: El FUEGO. Inconscientemente el jugar con fuego ayuda a disolver el miedo (campamentos fogones) | AV3: SOCIAL. Dignidad: Palabra sagrada. Evitar la burla. Nace la verdadera solidaridad que disuelve el miedo al otro. Enseñarle a valorarse y el valor del otro. | AX3: VISTA. Enseñar a ver más allá, a través de un microscopio, un telescopio o acostarse en el pasto y mirar el cielo. Ver juntos videos o películas y comentarlas.
B4: 2 | C4: 6 | I4: =+AFIRMACIONES!B31 -> 0 | M4: 101 | N4: 7 | U4: =+AFIRMACIONES!B130 -> 0 | X4: 200 | Y4: 3 | AB4: =+AFIRMACIONES!B229 -> 0 | AJ4: =+IF(AND(AFIRMACIONES!$C$6>=AL4,AFIRMACIONES!$C$6<=AM4),1,0) -> 0 | AK4: 3 | AL4: 14 | AM4: 20 | AN4: Afirmación | AO4: De 14 a 21 Años | AP4: Al CAMBIO. Todo cambia en la vida. Se constituye como persona. Necesita tomar distancia. Se produce el proceso hormonal de la adolescencia. | AR4: SEGURIDAD. Dejarlo actuar, pero estar cuando lo necesite. Ser un referente o "faro". Que sepa que "puede contar con uno". Mostrarle coherencia y consistencia. | AT4: El AIRE. Incentivar la vida al aire libre. Trabajar la respiración. Ir de campamento, correr, andar en bicicleta. | AV4: EXISTENCIAL. Etapa de preguntas sobre la vida y la muerte, aprender a ser crítico, a cuestionarse. Flexibilizar las normas y mantener firmes los valores. | AX4: TACTO. La música y el arte lo preparan para el amor. Hacer trabajos manuales, artesanías, sentir las cosas para lograr sensibilidad. Tocar un instrumento
B5: 3 | C5: 9 | L5: =+AFIRMACIONES!B32 -> 0 | M5: 102 | N5: 6 | T5: =+AFIRMACIONES!B131 -> 0 | X5: 201 | Y5: 4 | AC5: =+AFIRMACIONES!B230 -> 0 | AJ5: =+IF(AND(AFIRMACIONES!$C$6>=AL5,AFIRMACIONES!$C$6<=AM5),1,0) -> 0 | AK5: 4 | AL5: 21 | AM5: 27 | AN5: Afirmación | AO5: De 21 a 28 Años | AP5: A la CONTINUIDAD, a perder la libertad, a la rutina. Le cuesta asumir compromisos. La rutina está dentro de cada uno. | AR5: CREATIVIDAD. Lograr una actitud distinta hacia lo cotidiano, que sea placentero. Hacer extraordinario lo ordinario de cada día | AT5: La TIERRA enseña que no todo en la vida es invierno o verano, también existe la primavera y el otoño, la rutina no existe, son ciclos naturales. | AV5: TRANSPERSONAL. Etapa de los ¿para qué?. Encontrar el verdadero sentido de la vida. Buscar la misión de vida. ¿Para qué estoy? ¿A dónde voy? | AX5: OLFATO. Relacionado con la glándula pineal. Tiene que ver con el sentido común. Actualmente es el sentido menos desarrollado.
B6: 4 | C6: 3 | F6: =+AFIRMACIONES!B33 -> 0 | M6: 103 | N6: 3 | Q6: =+AFIRMACIONES!B132 -> 0 | X6: 202 | Y6: 9 | AH6: =+AFIRMACIONES!B231 -> 0 | AJ6: =+IF(AND(AFIRMACIONES!$C$6>=AL6,AFIRMACIONES!$C$6<=AM6),1,0) -> 0 | AK6: 5 | AL6: 28 | AM6: 41 | AN6: Afirmación | AO6: De 28 a 35 y de 35 a 42 Años | AP6: A PERDER la figura, la pareja, la virilidad, el dinero, la vida, lo que me gusta hacer. Miedo a perder el tiempo y la juventud. | AR6: SER. El tener compulsivamente disminuye solo momentáneamente el miedo a perder. Poner tiempo y energía para el ser, crecimiento interior. | AT6: La LUZ. Contacto con el sol para aprender a sentir la luz. Tiempo para tener claridad, para la soledad, no aislamiento, sino encontrarse con sí mismo. | AV6: UNIDAD. Conciencia comunitaria. Pensar en plural: "no soy, somos", "no es mío, es nuestro". Estar en armonía y agradecer y sonreír a la vida. | AX6: OÍDO. Escuchar el doble de lo que se habla. Aprender a escuchar y a escucharse. Prestar atención a lo sagrado en uno. Estar a la escucha.
B7: 5 | C7: 2 | E7: =+AFIRMACIONES!B34 -> 0 | M7: 104 | N7: 4 | R7: =+AFIRMACIONES!B133 -> 0 | X7: 203 | Y7: 2 | AA7: =+AFIRMACIONES!B232 -> 0 | AJ7: =+IF(AND(AFIRMACIONES!$C$6>=AL7,AFIRMACIONES!$C$6<=AM7),1,0) -> 0 | AK7: 6 | AL7: 42 | AM7: 48 | AN7: Transformación | AO7: De 42 a 49 Años | AP7: A la CONTINUIDAD, a la rutina. TENER: Aferrarse a los bienes y sólo tomarse recreos placenteros. Es necesario consolidar el SER. | AR7: CREATIVIDAD. Lograr una actitud distinta hacia lo cotidiano, hacer extraordinario lo ordinario. SER: Expansión de la persona | AT7: La TIERRA: energía de vida y de creación. Tomar contacto con la tierra, caminar, atender el jardín, regar. | AV7: TRANSPERSONAL. No encerrarse en la preocupaciones inmediatas. Focalizarse en el Ideal de Vida | AX7: OLFATO. Actuar con sentido común. Desarrolla el hemisferio derecho del cerebro. Disfrutar las esencias y sabiduría oculta en los aromas.
B8: 6 | C8: 5 | H8: =+AFIRMACIONES!B35 -> 0 | M8: 105 | N8: 2 | P8: =+AFIRMACIONES!B134 -> 0 | X8: 204 | Y8: 1 | Z8: =+AFIRMACIONES!B233 -> 0 | AJ8: =+IF(AND(AFIRMACIONES!$C$6>=AL8,AFIRMACIONES!$C$6<=AM8),1,0) -> 0 | AK8: 7 | AL8: 49 | AM8: 55 | AN8: Transformación | AO8: De 49 a 56 Años | AP8: Al CAMBIO, temor por los cambios físicos que comienzan: andropausia, menopausia. Nido vacío lleva al reencuentro de la pareja. La experiencia ayuda a ser guías. | AR8: SEGURIDAD, el tener da seguridad afuera: en lo material, el éxito; acción dirigida al trabajo para llenar vacíos. Pero el SER da seguridad en la plenitud personal. Amistad. | AT8: El AIRE, incentivar la vida al aire libre. Vivir sin fronteras, liberarse de las emociones. | AV8: EXISTENCIAL. El tener lleva a caer en la crítica, el pesimismo. El SER implica momento de cambios auténticos. Persona positiva que colabora y participa por el bien. | AX8: TACTO. Momento de sacar a la luz hobbies latentes. Masajes. Abrazos. Redescubrir el amor en la pareja.
B9: 7 | C9: 7 | J9: =+AFIRMACIONES!B36 -> 0 | M9: 106 | N9: 1 | O9: =+AFIRMACIONES!B135 -> 0 | X9: 205 | Y9: 8 | AG9: =+AFIRMACIONES!B234 -> 0 | AJ9: =+IF(AND(AFIRMACIONES!$C$6>=AL9,AFIRMACIONES!$C$6<=AM9),1,0) -> 0 | AK9: 8 | AL9: 56 | AM9: 62 | AN9: Transformación | AO9: De 56 a 63 Años | AP9: A la CERCANÍA A LOS OTROS, a robos, a sufrir violencia. Lleva a la persona a encerrase, no salir. Miedo a lo que puede pasar a los hijos y nietos. | AR9: AUTONOMÍA. No dejar de tomar recaudos, pero abrirse a la vida. Participar del "bien común" | AT9: El FUEGO le aporta vitalidad renovadora. El asado, lo culinario, cocinar para los demás con amor. | AV9: SOCIAL. Servicio social a través de lo experimentado. Solidaridad y participación. No caer en la amargura y la desesperanza | AX9: VISTA. Ejercitar la capacidad de asombro. Aprender cosas nuevas. Ser visionarios.
B10: 8 | C10: 4 | G10: =+AFIRMACIONES!B37 -> 0 | M10: 107 | N10: 8 | V10: =+AFIRMACIONES!B136 -> 0 | X10: 206 | Y10: 6 | AE10: =+AFIRMACIONES!B235 -> 0 | AJ10: =+IF(AND(AFIRMACIONES!$C$6>=AL10,AFIRMACIONES!$C$6<=AM10),1,0) -> 0 | AK10: 9 | AL10: 63 | AM10: 69 | AN10: Transformación | AO10: De 63 a 70 Años | AP10: A la DISTANCIA, a sentirse inútil, sensación de abandono. Reclama presencia, tiempo y energía. | AR10: PRESENCIA. Acompañamiento, presencia y servicio no invasivos, no tóxicos. Sabiduría en límites sanos. | AT10: El AGUA disuelve el miedo. Es sanante. Alarma de problemas psicológicos si hay rechazo a la higiene. | AV10: YO. Si se afirma el ego = Tóxico, si se afirma la conciencia = Sabio. Autoestima sana. | AX10: GUSTO. Saborear = sabiduría. Cuidarse y comer bien. En sombra hipocondríacos.
B11: 9 | C11: 1 | D11: =+AFIRMACIONES!B38 -> 0 | M11: 108 | N11: 9 | W11: =+AFIRMACIONES!B137 -> 0 | X11: 207 | Y11: 5 | AD11: =+AFIRMACIONES!B236 -> 0 | AJ11: =+IF(AND(AFIRMACIONES!$C$6>=AL11,AFIRMACIONES!$C$6<=AM11),1,0) -> 0 | AK11: 10 | AL11: 70 | AM11: 90 | AN11: Transformación | AO11: De 70 en adelante | AP11: A PERDER, a la muerte. La muerte como final o como paso a la trascendencia. | AR11: SER. Momento de confirmar las decisiones fundamentales de la vida. Durar o madurar. Servir. | AT11: La LUZ, tomar contacto con el sol. Los ojos son las ventanas del alma. Ser faros que iluminan. (una cosa es querer brillar y otra ser luz). | AV11: UNIDAD. La casa de los abuelos es el corazón de la familia. Tener gratitud y alegría. | AX11: OÍDO. Ser expertos en el arte de escuchar. En la sombra hablar de sí, criticar y dar consejos que no le piden.
B12: 10 | C12: 9 | L12: =+AFIRMACIONES!B39 -> 0 | M12: 109 | N12: 2 | P12: =+AFIRMACIONES!B138 -> 0 | X12: 208 | Y12: 5 | AD12: =+AFIRMACIONES!B237 -> 0
B13: 11 | C13: 4 | G13: =+AFIRMACIONES!B40 -> 0 | M13: 110 | N13: 7 | U13: =+AFIRMACIONES!B139 -> 0 | X13: 209 | Y13: 2 | AA13: =+AFIRMACIONES!B238 -> 0
B14: 12 | C14: 7 | J14: =+AFIRMACIONES!B41 -> 0 | M14: 111 | N14: 8 | V14: =+AFIRMACIONES!B140 -> 0 | X14: 210 | Y14: 3 | AB14: =+AFIRMACIONES!B239 -> 0
B15: 13 | C15: 8 | K15: =+AFIRMACIONES!B42 -> 0 | M15: 112 | N15: 5 | S15: =+AFIRMACIONES!B141 -> 0 | X15: 211 | Y15: 1 | Z15: =+AFIRMACIONES!B240 -> 0
B16: 14 | C16: 3 | F16: =+AFIRMACIONES!B43 -> 0 | M16: 113 | N16: 3 | Q16: =+AFIRMACIONES!B142 -> 0 | X16: 212 | Y16: 6 | AE16: =+AFIRMACIONES!B241 -> 0
B17: 15 | C17: 1 | D17: =+AFIRMACIONES!B44 -> 0 | M17: 114 | N17: 4 | R17: =+AFIRMACIONES!B143 -> 0 | X17: 213 | Y17: 9 | AH17: =+AFIRMACIONES!B242 -> 0
B18: 16 | C18: 6 | I18: =+AFIRMACIONES!B45 -> 0 | M18: 115 | N18: 6 | T18: =+AFIRMACIONES!B144 -> 0 | X18: 214 | Y18: 4 | AC18: =+AFIRMACIONES!B243 -> 0
B19: 17 | C19: 2 | E19: =+AFIRMACIONES!B46 -> 0 | M19: 116 | N19: 1 | O19: =+AFIRMACIONES!B145 -> 0 | X19: 215 | Y19: 8 | AG19: =+AFIRMACIONES!B244 -> 0
B20: 18 | C20: 5 | H20: =+AFIRMACIONES!B47 -> 0 | M20: 117 | N20: 9 | W20: =+AFIRMACIONES!B146 -> 0 | X20: 216 | Y20: 7 | AF20: =+AFIRMACIONES!B245 -> 0
B21: 19 | C21: 8 | K21: =+AFIRMACIONES!B48 -> 0 | M21: 118 | N21: 3 | Q21: =+AFIRMACIONES!B147 -> 0 | X21: 217 | Y21: 3 | AB21: =+AFIRMACIONES!B246 -> 0
B22: 20 | C22: 5 | H22: =+AFIRMACIONES!B49 -> 0 | M22: 119 | N22: 7 | U22: =+AFIRMACIONES!B148 -> 0 | X22: 218 | Y22: 4 | AC22: =+AFIRMACIONES!B247 -> 0
B23: 21 | C23: 2 | E23: =+AFIRMACIONES!B50 -> 0 | M23: 120 | N23: 1 | O23: =+AFIRMACIONES!B149 -> 0 | X23: 219 | Y23: 7 | AF23: =+AFIRMACIONES!B248 -> 0
B24: 22 | C24: 4 | G24: =+AFIRMACIONES!B51 -> 0 | M24: 121 | N24: 5 | S24: =+AFIRMACIONES!B150 -> 0 | X24: 220 | Y24: 9 | AH24: =+AFIRMACIONES!B249 -> 0
B25: 23 | C25: 7 | J25: =+AFIRMACIONES!B52 -> 0 | M25: 122 | N25: 2 | P25: =+AFIRMACIONES!B151 -> 0 | X25: 221 | Y25: 8 | AG25: =+AFIRMACIONES!B250 -> 0
B26: 24 | C26: 1 | D26: =+AFIRMACIONES!B53 -> 0 | M26: 123 | N26: 4 | R26: =+AFIRMACIONES!B152 -> 0 | X26: 222 | Y26: 5 | AD26: =+AFIRMACIONES!B251 -> 0
B27: 25 | C27: 9 | L27: =+AFIRMACIONES!B54 -> 0 | M27: 124 | N27: 8 | V27: =+AFIRMACIONES!B153 -> 0 | X27: 223 | Y27: 1 | Z27: =+AFIRMACIONES!B252 -> 0
B28: 26 | C28: 3 | F28: =+AFIRMACIONES!B55 -> 0 | M28: 125 | N28: 9 | W28: =+AFIRMACIONES!B154 -> 0 | X28: 224 | Y28: 2 | AA28: =+AFIRMACIONES!B253 -> 0
B29: 27 | C29: 6 | I29: =+AFIRMACIONES!B56 -> 0 | M29: 126 | N29: 6 | T29: =+AFIRMACIONES!B155 -> 0 | X29: 225 | Y29: 6 | AE29: =+AFIRMACIONES!B254 -> 0
B30: 28 | C30: 2 | E30: =+AFIRMACIONES!B57 -> 0 | M30: 127 | N30: 6 | T30: =+AFIRMACIONES!B156 -> 0 | X30: 226 | Y30: 1 | Z30: =+AFIRMACIONES!B255 -> 0
B31: 29 | C31: 3 | F31: =+AFIRMACIONES!B58 -> 0 | M31: 128 | N31: 1 | O31: =+AFIRMACIONES!B157 -> 0 | X31: 227 | Y31: 2 | AA31: =+AFIRMACIONES!B256 -> 0
B32: 30 | C32: 8 | K32: =+AFIRMACIONES!B59 -> 0 | M32: 129 | N32: 2 | P32: =+AFIRMACIONES!B158 -> 0 | X32: 228 | Y32: 5 | AD32: =+AFIRMACIONES!B257 -> 0
B33: 31 | C33: 5 | H33: =+AFIRMACIONES!B60 -> 0 | M33: 130 | N33: 8 | V33: =+AFIRMACIONES!B159 -> 0 | X33: 229 | Y33: 6 | AE33: =+AFIRMACIONES!B258 -> 0
B34: 32 | C34: 1 | D34: =+AFIRMACIONES!B61 -> 0 | M34: 131 | N34: 3 | Q34: =+AFIRMACIONES!B160 -> 0 | X34: 230 | Y34: 8 | AG34: =+AFIRMACIONES!B259 -> 0
B35: 33 | C35: 6 | I35: =+AFIRMACIONES!B62 -> 0 | M35: 132 | N35: 7 | U35: =+AFIRMACIONES!B161 -> 0 | X35: 231 | Y35: 9 | AH35: =+AFIRMACIONES!B260 -> 0
B36: 34 | C36: 9 | L36: =+AFIRMACIONES!B63 -> 0 | M36: 133 | N36: 5 | S36: =+AFIRMACIONES!B162 -> 0 | X36: 232 | Y36: 4 | AC36: =+AFIRMACIONES!B261 -> 0
B37: 35 | C37: 4 | G37: =+AFIRMACIONES!B64 -> 0 | M37: 134 | N37: 4 | R37: =+AFIRMACIONES!B163 -> 0 | X37: 233 | Y37: 7 | AF37: =+AFIRMACIONES!B262 -> 0
B38: 36 | C38: 7 | J38: =+AFIRMACIONES!B65 -> 0 | M38: 135 | N38: 9 | W38: =+AFIRMACIONES!B164 -> 0 | X38: 234 | Y38: 3 | AB38: =+AFIRMACIONES!B263 -> 0
B39: 37 | C39: 4 | G39: =+AFIRMACIONES!B66 -> 0 | M39: 136 | N39: 9 | W39: =+AFIRMACIONES!B165 -> 0 | X39: 235 | Y39: 8 | AG39: =+AFIRMACIONES!B264 -> 0
B40: 38 | C40: 5 | H40: =+AFIRMACIONES!B67 -> 0 | M40: 137 | N40: 6 | T40: =+AFIRMACIONES!B166 -> 0 | X40: 236 | Y40: 9 | AH40: =+AFIRMACIONES!B265 -> 0
...

Sheet ENEGRAMA ANTERIOR
AN1: CICLO | AO1: ETAPA | AP1: MIEDO | AR1: ACTITUD | AT1: ELEMENTO | AV1: NIVEL CONCIENTE | AX1: SENTIDO
AJ2: =+IF(AND($K$112>=AL2,$K$112<=AM2),1,0) -> 0 | AK2: 1 | AL2: 1 | AM2: 6 | AN2: Afirmación | AO2: De O a 7 Años | AP2: A la DISTANCIA, al abandono. Lo agrava la muerte de un ser querido o una mascota o la separación de los padres. | AR2: PRESENCIA, estar presente con el corazón. Presencia cualitativa y cuantitativa. Acompañarlo. Necesita la figura materna y paterna. | AT2: El AGUA, disuelve el miedo. Recuerda al líquido amniótico. Es sanante. | AV2: YO. Afianzar el yo personal. Poner límites claros y precisos sin mayores explicaciones. Sólo en esta etapa funciona el "premio - castigo". | AX2: GUSTO. Es importante variar su alimentación para que sepa que existe lo dulce, lo salado y lo amargo. Aprende que no todo lo que le gusta es nutritivo.
AJ3: =+IF(AND($K$112>=AL3,$K$112<=AM3),1,0) -> 0 | AK3: 2 | AL3: 7 | AM3: 13 | AN3: Afirmación | AO3: De 7 a 14 Años | AP3: A la CERCANÍA, a LOS OTROS, a que nadie lo quiera, no agradarle al otro, al rechazo o a que le hagan mal. | AR3: AUTONOMÍA, ayudarlo a que enfrente las situaciones por sí mismo y decidan. Estar cerca y acompañarlo. Darle explicaciones. "La norma se apoya en un valor" | AT3: El FUEGO. Inconscientemente el jugar con fuego ayuda a disolver el miedo (campamentos fogones) | AV3: SOCIAL. Dignidad: Palabra sagrada. Evitar la burla. Nace la verdadera solidaridad que disuelve el miedo al otro. Enseñarle a valorarse y el valor del otro. | AX3: VISTA. Enseñar a ver más allá, a través de un microscopio, un telescopio o acostarse en el pasto y mirar el cielo. Ver juntos videos o películas y comentarlas.
AJ4: =+IF(AND($K$112>=AL4,$K$112<=AM4),1,0) -> 0 | AK4: 3 | AL4: 14 | AM4: 20 | AN4: Afirmación | AO4: De 14 a 21 Años | AP4: Al CAMBIO. Todo cambia en la vida. Se constituye como persona. Necesita tomar distancia. Se produce el proceso hormonal de la adolescencia. | AR4: SEGURIDAD. Dejarlo actuar, pero estar cuando lo necesite. Ser un referente o "faro". Que sepa que "puede contar con uno". Mostrarle coherencia y consistencia. | AT4: El AIRE. Incentivar la vida al aire libre. Trabajar la respiración. Ir de campamento, correr, andar en bicicleta. | AV4: EXISTENCIAL. Etapa de preguntas sobre la vida y la muerte, aprender a ser crítico, a cuestionarse. Flexibilizar las normas y mantener firmes los valores. | AX4: TACTO. La música y el arte lo preparan para el amor. Hacer trabajos manuales, artesanías, sentir las cosas para lograr sensibilidad. Tocar un instrumento
AJ5: =+IF(AND($K$112>=AL5,$K$112<=AM5),1,0) -> 0 | AK5: 4 | AL5: 21 | AM5: 27 | AN5: Afirmación | AO5: De 21 a 28 Años | AP5: A la CONTINUIDAD, a perder la libertad, a la rutina. Le cuesta asumir compromisos. La rutina está dentro de cada uno. | AR5: CREATIVIDAD. Lograr una actitud distinta hacia lo cotidiano, que sea placentero. Hacer extraordinario lo ordinario de cada día | AT5: La TIERRA enseña que no todo en la vida es invierno o verano, también existe la primavera y el otoño, la rutina no existe, son ciclos naturales. | AV5: TRANSPERSONAL. Etapa de los ¿para qué?. Encontrar el verdadero sentido de la vida. Buscar la misión de vida. ¿Para qué estoy? ¿A dónde voy? | AX5: OLFATO. Relacionado con la glándula pineal. Tiene que ver con el sentido común. Actualmente es el sentido menos desarrollado.
AJ6: =+IF(AND($K$112>=AL6,$K$112<=AM6),1,0) -> 0 | AK6: 5 | AL6: 28 | AM6: 41 | AN6: Afirmación | AO6: De 28 a 35 y de 35 a 42 Años | AP6: A PERDER la figura, la pareja, la virilidad, el dinero, la vida, lo que me gusta hacer. Miedo a perder el tiempo y la juventud. | AR6: SER. El tener compulsivamente disminuye solo momentáneamente el miedo a perder. Poner tiempo y energía para el ser, crecimiento interior. | AT6: La LUZ. Contacto con el sol para aprender a sentir la luz. Tiempo para tener claridad, para la soledad, no aislamiento, sino encontrarse con sí mismo. | AV6: UNIDAD. Conciencia comunitaria. Pensar en plural: "no soy, somos", "no es mío, es nuestro". Estar en armonía y agradecer y sonreír a la vida. | AX6: OÍDO. Escuchar el doble de lo que se habla. Aprender a escuchar y a escucharse. Prestar atención a lo sagrado en uno. Estar a la escucha.
AJ7: =+IF(AND($K$112>=AL7,$K$112<=AM7),1,0) -> 0 | AK7: 6 | AL7: 42 | AM7: 48 | AN7: Transformación | AO7: De 42 a 49 Años | AP7: A la CONTINUIDAD, a la rutina. TENER: Aferrarse a los bienes y sólo tomarse recreos placenteros. Es necesario consolidar el SER. | AR7: CREATIVIDAD. Lograr una actitud distinta hacia lo cotidiano, hacer extraordinario lo ordinario. SER: Expansión de la persona | AT7: La TIERRA: energía de vida y de creación. Tomar contacto con la tierra, caminar, atender el jardín, regar. | AV7: TRANSPERSONAL. No encerrarse en la preocupaciones inmediatas. Focalizarse en el Ideal de Vida | AX7: OLFATO. Actuar con sentido común. Desarrolla el hemisferio derecho del cerebro. Disfrutar las esencias y sabiduría oculta en los aromas.
AJ8: =+IF(AND($K$112>=AL8,$K$112<=AM8),1,0) -> 0 | AK8: 7 | AL8: 49 | AM8: 55 | AN8: Transformación | AO8: De 49 a 56 Años | AP8: Al CAMBIO, temor por los cambios físicos que comienzan: andropausia, menopausia. Nido vacío lleva al reencuentro de la pareja. La experiencia ayuda a ser guías. | AR8: SEGURIDAD, el tener da seguridad afuera: en lo material, el éxito; acción dirigida al trabajo para llenar vacíos. Pero el SER da seguridad en la plenitud personal. Amistad. | AT8: El AIRE, incentivar la vida al aire libre. Vivir sin fronteras, liberarse de las emociones. | AV8: EXISTENCIAL. El tener lleva a caer en la crítica, el pesimismo. El SER implica momento de cambios auténticos. Persona positiva que colabora y participa por el bien. | AX8: TACTO. Momento de sacar a la luz hobbies latentes. Masajes. Abrazos. Redescubrir el amor en la pareja.
AJ9: =+IF(AND($K$112>=AL9,$K$112<=AM9),1,0) -> 0 | AK9: 8 | AL9: 56 | AM9: 62 | AN9: Transformación | AO9: De 56 a 63 Años | AP9: A la CERCANÍA A LOS OTROS, a robos, a sufrir violencia. Lleva a la persona a encerrase, no salir. Miedo a lo que puede pasar a los hijos y nietos. | AR9: AUTONOMÍA. No dejar de tomar recaudos, pero abrirse a la vida. Participar del "bien común" | AT9: El FUEGO le aporta vitalidad renovadora. El asado, lo culinario, cocinar para los demás con amor. | AV9: SOCIAL. Servicio social a través de lo experimentado. Solidaridad y participación. No caer en la amargura y la desesperanza | AX9: VISTA. Ejercitar la capacidad de asombro. Aprender cosas nuevas. Ser visionarios.
AJ10: =+IF(AND($K$112>=AL10,$K$112<=AM10),1,0) -> 0 | AK10: 9 | AL10: 63 | AM10: 69 | AN10: Transformación | AO10: De 63 a 70 Años | AP10: A la DISTANCIA, a sentirse inútil, sensación de abandono. Reclama presencia, tiempo y energía. | AR10: PRESENCIA. Acompañamiento, presencia y servicio no invasivos, no tóxicos. Sabiduría en límites sanos. | AT10: El AGUA disuelve el miedo. Es sanante. Alarma de problemas psicológicos si hay rechazo a la higiene. | AV10: YO. Si se afirma el ego = Tóxico, si se afirma la conciencia = Sabio. Autoestima sana. | AX10: GUSTO. Saborear = sabiduría. Cuidarse y comer bien. En sombra hipocondríacos.
AJ11: =+IF(AND($K$112>=AL11,$K$112<=AM11),1,0) -> 0 | AK11: 10 | AL11: 70 | AM11: 90 | AN11: Transformación | AO11: De 70 en adelante | AP11: A PERDER, a la muerte. La muerte como final o como paso a la trascendencia. | AR11: SER. Momento de confirmar las decisiones fundamentales de la vida. Durar o madurar. Servir. | AT11: La LUZ, tomar contacto con el sol. Los ojos son las ventanas del alma. Ser faros que iluminan. (una cosa es querer brillar y otra ser luz). | AV11: UNIDAD. La casa de los abuelos es el corazón de la familia. Tener gratitud y alegría. | AX11: OÍDO. Ser expertos en el arte de escuchar. En la sombra hablar de sí, criticar y dar consejos que no le piden.
AI79: Total
AI80: Afirmaciones
AI81: Respondidas
X82: Totales | Z82: =+G108 -> 0 | AA82: =+H108 -> 0 | AB82: =+I108 -> 0 | AC82: =+J108 -> 0 | AD82: =+K108 -> 0 | AE82: =+L108 -> 0 | AF82: =+M108 -> 0 | AG82: =+N108 -> 0 | AH82: =+O108 -> 0 | AI82: =SUM(Z82:AH82) -> 0
Z84: Parámetro para cálculo de eje de equilibrio: si la media es hasta 13, hay eje con diferencia en extremos de hasta 2 puntos, si la media es mayor que 13, hay eje con diferencia en extremos de hasta 3 puntos. | AG84: =IF(H176<=13,2,3) -> 2
X90: =+B183 -> 0 | Y90: =+IF(X90<0, 1,) -> 0 | Z90: 1 | AA90: Libertad - Salir de estructuras o situaciones que asfixian.
X91: =+C183 -> 0 | Y91: =+IF(X91<0, 1,) -> 0 | Z91: 2 | AA91: Abrirse afectivamente, a la vincularidad - Amar.
X92: =+D183 -> 0 | Y92: =+IF(X92<0, 1,) -> 0 | Z92: 3 | AA92: Hacer lo que se debe para lograr el desarrollo personal.
X93: =+E183 -> 0 | Y93: =+IF(X93<0, 1,) -> 0 | Z93: 4 | AA93: Introspección - Mirar lo que no le gusta o no puede cambiar de si.
X94: =+F183 -> 0 | Y94: =+IF(X94<0, 1,) -> 0 | Z94: 5 | AA94: Ver la realidad, lo que no quiere o no puede ver o aceptar.
X95: =+G183 -> 0 | Y95: =+IF(X95<0, 1,) -> 0 | Z95: 6 | AA95: Libertad - Revisar obligaciones o compromisos que se ha creado.
X96: =+H183 -> 0 | Y96: =+IF(X96<0, 1,) -> 0 | Z96: 7 | AA96: Disfrutar - Relejarse de exceso de responsabilidades y control.
X97: =+I183 -> 0 | Y97: =+IF(X97<0, 1,) -> 0 | Z97: 8 | AA97: Una decisión - Poner límites - Considerar las consecuencias.
X98: =+J183 -> 0 | Y98: =+IF(X98<0, 1,) -> 0 | Z98: 9 | AA98: Parar - Delegar - Salir de la adicción a la actividad.
B104: Si dispones de un Eneagrama anterior y deseas compararlo con tu nuevo Eneagrama,
K105: introduce aquí el valor de los Atributos que tenía ese Eneagrama anterior:
G106: VALOR DE LOS ATRIBUTOS:
G107: 1 | H107: 2 | I107: 3 | J107: 4 | K107: 5 | L107: 6 | M107: 7 | N107: 8 | O107: 9
B109: Introduce en el siguiente recuadro la fecha en que hiciste tu Eneagrama anterior con formato dd/mm/aaaa:
B111: Introduce en el siguiente recuadro tu edad al momento de realizar tu Eneagrama anterior (sólo el número):
K114: Completados estos datos, verifica si a continuación aparece tu nombre, si no tipéalo y luego imprime esta hoja con tu Eneagrama anterior.
B115: ENEAGRAMA DE :
Q116: FECHA del ENEAGRAMA: | R116: =+M172 -> 0
B118: Importante: El ENEAGRAMA no es un test de personalidad, no siempre el valor más alto de los Atributos corresponde a la Esencia de la persona
O119: Versión
B120: MEDIA: | D120: =(MAX($B$174:$J$174)+MIN($B$174:$J$174))/2 -> 0
K134: =+J174 -> 0
E140: =+I174 -> 0 | Q140: =+B174 -> 0
E148: =+H174 -> 0 | Q148: =+C174 -> 0
...
